Workbook

Sheet Database
F2: In €
B3: Category | C3: Process | D3: Make | E3: Model | F3: Machine Cost | G3: Machine Footprint SQM | H3: Power Consumption
B4: Rigids | C4: EBM | D4: Jomar | E4: Jomar 65 | F4: =_xlfn.XLOOKUP(E4,Rigids!$C:$C,Rigids!$D:$D,0) -> 323485 | G4: =_xlfn.XLOOKUP(E4,Rigids!$C:$C,Rigids!$G:$G,0) -> 40 | H4: =_xlfn.XLOOKUP(E4,Rigids!$C:$C,Rigids!$E:$E,0) -> 35
B5: Rigids | C5: EBM | D5: Jomar | E5: Jomar 135 | F5: =_xlfn.XLOOKUP(E5,Rigids!$C:$C,Rigids!$D:$D,0) -> 495662.5 | G5: =_xlfn.XLOOKUP(E5,Rigids!$C:$C,Rigids!$G:$G,0) -> 40 | H5: =_xlfn.XLOOKUP(E5,Rigids!$C:$C,Rigids!$E:$E,0) -> 80
B6: Rigids | C6: EBM | D6: Uniloy | E6: Uniloy | F6: =_xlfn.XLOOKUP(E6,Rigids!$C:$C,Rigids!$D:$D,0) -> 349572.5 | G6: =_xlfn.XLOOKUP(E6,Rigids!$C:$C,Rigids!$G:$G,0) -> 40 | H6: =_xlfn.XLOOKUP(E6,Rigids!$C:$C,Rigids!$E:$E,0) -> 65
B7: Rigids | C7: EBM | D7: Sika | E7: Sika | F7: =_xlfn.XLOOKUP(E7,Rigids!$C:$C,Rigids!$D:$D,0) -> 349572.5 | G7: =_xlfn.XLOOKUP(E7,Rigids!$C:$C,Rigids!$G:$G,0) -> 40 | H7: =_xlfn.XLOOKUP(E7,Rigids!$C:$C,Rigids!$E:$E,0) -> 65
B8: Rigids | C8: EBM | D8: Speedex | E8: Speedex | F8: =_xlfn.XLOOKUP(E8,Rigids!$C:$C,Rigids!$D:$D,0) -> 125220 | G8: =_xlfn.XLOOKUP(E8,Rigids!$C:$C,Rigids!$G:$G,0) -> 40 | H8: =_xlfn.XLOOKUP(E8,Rigids!$C:$C,Rigids!$E:$E,0) -> 65
B9: Rigids | C9: EBM | D9: Magic | E9: Magic 10 | F9: =_xlfn.XLOOKUP(E9,Rigids!$C:$C,Rigids!$D:$D,0) -> 1069587.5 | G9: =_xlfn.XLOOKUP(E9,Rigids!$C:$C,Rigids!$G:$G,0) -> 40 | H9: =_xlfn.XLOOKUP(E9,Rigids!$C:$C,Rigids!$E:$E,0) -> 125
B10: Rigids | C10: EBM | D10: BMU | E10: BMU 70 | F10: =_xlfn.XLOOKUP(E10,Rigids!$C:$C,Rigids!$D:$D,0) -> 357920.5 | G10: =_xlfn.XLOOKUP(E10,Rigids!$C:$C,Rigids!$G:$G,0) -> 40 | H10: =_xlfn.XLOOKUP(E10,Rigids!$C:$C,Rigids!$E:$E,0) -> 70
B11: Rigids | C11: EBM | D11: BMU | E11: BMU 100 | F11: =_xlfn.XLOOKUP(E11,Rigids!$C:$C,Rigids!$D:$D,0) -> 600012.5 | G11: =_xlfn.XLOOKUP(E11,Rigids!$C:$C,Rigids!$G:$G,0) -> 40 | H11: =_xlfn.XLOOKUP(E11,Rigids!$C:$C,Rigids!$E:$E,0) -> 70
B12: Rigids | C12: EBM | D12: SEB | E12: SEB 820 | F12: =_xlfn.XLOOKUP(E12,Rigids!$C:$C,Rigids!$D:$D,0) -> 1153067.5 | G12: =_xlfn.XLOOKUP(E12,Rigids!$C:$C,Rigids!$G:$G,0) -> 40 | H12: =_xlfn.XLOOKUP(E12,Rigids!$C:$C,Rigids!$E:$E,0) -> 130
B13: Rigids | C13: EBM | D13: Sidel | E13: Sidel EVO Blow SR 1/2 PH | F13: =_xlfn.XLOOKUP(E13,Rigids!$C:$C,Rigids!$D:$D,0) -> 125220 | G13: =_xlfn.XLOOKUP(E13,Rigids!$C:$C,Rigids!$G:$G,0) -> 20 | H13: =_xlfn.XLOOKUP(E13,Rigids!$C:$C,Rigids!$E:$E,0) -> 40
B14: Rigids | C14: EBM | D14: Bekum | E14: Bekum (dual-head / shuttle & rotary EBM family) | F14: =_xlfn.XLOOKUP(E14,Rigids!$C:$C,Rigids!$D:$D,0) -> 391312.5 | G14: =_xlfn.XLOOKUP(E14,Rigids!$C:$C,Rigids!$G:$G,0) -> 50 | H14: =_xlfn.XLOOKUP(E14,Rigids!$C:$C,Rigids!$E:$E,0) -> 90
B15: Rigids | C15: EBM | D15: Kautex | E15: Kautex / Nissei Kautex (dual-head rotary / shuttle) | F15: =_xlfn.XLOOKUP(E15,Rigids!$C:$C,Rigids!$D:$D,0) -> 495662.5 | G15: =_xlfn.XLOOKUP(E15,Rigids!$C:$C,Rigids!$G:$G,0) -> 71.5 | H15: =_xlfn.XLOOKUP(E15,Rigids!$C:$C,Rigids!$E:$E,0) -> 120
... B52: Rigids | C52: ISBM 1/1.5/2 | D52: ASB | E52: ASB 70 DPW | F52: =_xlfn.XLOOKUP(E52,Rigids!$C:$C,Rigids!$D:$D,0) -> 626100 | G52: =_xlfn.XLOOKUP(E52,Rigids!$C:$C,Rigids!$G:$G,0) -> 40 | H52: =_xlfn.XLOOKUP(E52,Rigids!$C:$C,Rigids!$E:$E,0) -> 125
B53: Rigids | C53: Robotic Arm | E53: Robotic Arm | F53: =_xlfn.XLOOKUP(E53,Rigids!$C:$C,Rigids!$D:$D,0) -> 50000 | G53: =_xlfn.XLOOKUP(E53,Rigids!$C:$C,Rigids!$G:$G,0) -> 0 | H53: =_xlfn.XLOOKUP(E53,Rigids!$C:$C,Rigids!$E:$E,0) -> 0
B54: Flexibles | C54: Gravure | D54: Bobst | E54: Bobst Lemanic Delta | F54: =_xlfn.XLOOKUP(E54,Flexibles!$C:$C,Flexibles!$D:$D,0) -> 3000000 | G54: =_xlfn.XLOOKUP(E54,Flexibles!$C:$C,Flexibles!$H:$H,0) -> 210 | H54: =_xlfn.XLOOKUP(E54,Flexibles!$C:$C,Flexibles!$G:$G,0) -> 180
B55: Flexibles | C55: Gravure | D55: Bobst | E55: Bobst Lemanic Rivera | F55: =_xlfn.XLOOKUP(E55,Flexibles!$C:$C,Flexibles!$D:$D,0) -> 3000000 | G55: =_xlfn.XLOOKUP(E55,Flexibles!$C:$C,Flexibles!$H:$H,0) -> 240 | H55: =_xlfn.XLOOKUP(E55,Flexibles!$C:$C,Flexibles!$G:$G,0) -> 180
B56: Flexibles | C56: Gravure | D56: Bobst | E56: Bobst RS6003 Expert | F56: =_xlfn.XLOOKUP(E56,Flexibles!$C:$C,Flexibles!$D:$D,0) -> 2500000 | G56: =_xlfn.XLOOKUP(E56,Flexibles!$C:$C,Flexibles!$H:$H,0) -> 154 | H56: =_xlfn.XLOOKUP(E56,Flexibles!$C:$C,Flexibles!$G:$G,0) -> 180
B57: Flexibles | C57: Gravure | D57: Bobst | E57: Bobst RS5003 Expert | F57: =_xlfn.XLOOKUP(E57,Flexibles!$C:$C,Flexibles!$D:$D,0) -> 2500000 | G57: =_xlfn.XLOOKUP(E57,Flexibles!$C:$C,Flexibles!$H:$H,0) -> 120 | H57: =_xlfn.XLOOKUP(E57,Flexibles!$C:$C,Flexibles!$G:$G,0) -> 180
B58: Flexibles | C58: Gravure | D58: Bobst | E58: Bobst Expert MW 60 I 80 | F58: =_xlfn.XLOOKUP(E58,Flexibles!$C:$C,Flexibles!$D:$D,0) -> 1800000 | G58: =_xlfn.XLOOKUP(E58,Flexibles!$C:$C,Flexibles!$H:$H,0) -> 110 | H58: =_xlfn.XLOOKUP(E58,Flexibles!$C:$C,Flexibles!$G:$G,0) -> 180
B59: Flexibles | C59: Gravure | D59: Bobst | E59: Bobst Expert GP 500 | F59: =_xlfn.XLOOKUP(E59,Flexibles!$C:$C,Flexibles!$D:$D,0) -> 1800000 | G59: =_xlfn.XLOOKUP(E59,Flexibles!$C:$C,Flexibles!$H:$H,0) -> 180 | H59: =_xlfn.XLOOKUP(E59,Flexibles!$C:$C,Flexibles!$G:$G,0) -> 180
B60: Flexibles | C60: Gravure | D60: Bobst | E60: Bobst Expert GP 700 | F60: =_xlfn.XLOOKUP(E60,Flexibles!$C:$C,Flexibles!$D:$D,0) -> 1800000 | G60: =_xlfn.XLOOKUP(E60,Flexibles!$C:$C,Flexibles!$H:$H,0) -> 208 | H60: =_xlfn.XLOOKUP(E60,Flexibles!$C:$C,Flexibles!$G:$G,0) -> 180
B61: Flexibles | C61: Gravure | D61: Miraflex | E61: Miraflex 70+ M | F61: =_xlfn.XLOOKUP(E61,Flexibles!$C:$C,Flexibles!$D:$D,0) -> 1500000 | G61: =_xlfn.XLOOKUP(E61,Flexibles!$C:$C,Flexibles!$H:$H,0) -> 56 | H61: =_xlfn.XLOOKUP(E61,Flexibles!$C:$C,Flexibles!$G:$G,0) -> 180
B62: Flexibles | C62: Gravure | D62: Miraflex | E62: Miraflex 70+ L | F62: =_xlfn.XLOOKUP(E62,Flexibles!$C:$C,Flexibles!$D:$D,0) -> 1500000 | G62: =_xlfn.XLOOKUP(E62,Flexibles!$C:$C,Flexibles!$H:$H,0) -> 56 | H62: =_xlfn.XLOOKUP(E62,Flexibles!$C:$C,Flexibles!$G:$G,0) -> 180
B63: Flexibles | C63: Gravure | D63: Cerutti | E63: Cerutti R982 | F63: =_xlfn.XLOOKUP(E63,Flexibles!$C:$C,Flexibles!$D:$D,0) -> 1800000 | G63: =_xlfn.XLOOKUP(E63,Flexibles!$C:$C,Flexibles!$H:$H,0) -> 81 | H63: =_xlfn.XLOOKUP(E63,Flexibles!$C:$C,Flexibles!$G:$G,0) -> 180
B64: Flexibles | C64: Gravure | D64: Huitong | E64: Huitong HD-Type ELS | F64: =_xlfn.XLOOKUP(E64,Flexibles!$C:$C,Flexibles!$D:$D,0) -> 1800000 | G64: =_xlfn.XLOOKUP(E64,Flexibles!$C:$C,Flexibles!$H:$H,0) -> 90 | H64: =_xlfn.XLOOKUP(E64,Flexibles!$C:$C,Flexibles!$G:$G,0) -> 180
B65: Flexibles | C65: Gravure | D65: Huitong | E65: Huitong ZD-Type ELS | F65: =_xlfn.XLOOKUP(E65,Flexibles!$C:$C,Flexibles!$D:$D,0) -> 1450000 | G65: =_xlfn.XLOOKUP(E65,Flexibles!$C:$C,Flexibles!$H:$H,0) -> 90 | H65: =_xlfn.XLOOKUP(E65,Flexibles!$C:$C,Flexibles!$G:$G,0) -> 180
... B125: Flexibles | C125: Glueing | D125: KETE | E125: KETE | F125: =_xlfn.XLOOKUP(E125,Flexibles!$C:$C,Flexibles!$D:$D,0) -> 30000 | G125: =_xlfn.XLOOKUP(E125,Flexibles!$C:$C,Flexibles!$H:$H,0) -> 9.6 | H125: =_xlfn.XLOOKUP(E125,Flexibles!$C:$C,Flexibles!$G:$G,0) -> 5
B126: Tubes | C126: Compression Molding | D126: Packsys | E126: Focus 40 | F126: 900000 | G126: =_xlfn.XLOOKUP($E$126,Tubes!$D:$D,Tubes!$J:$J,0) -> 20 | H126: =_xlfn.XLOOKUP($E$126,Tubes!$D:$D,Tubes!$K:$K,0) -> 22
B127: Tubes | C127: Compression Molding | D127: Packsys | E127: Focus 80 | F127: 1500000 | G127: =_xlfn.XLOOKUP($E$126,Tubes!$D:$D,Tubes!$J:$J,0) -> 20 | H127: =_xlfn.XLOOKUP($E$126,Tubes!$D:$D,Tubes!$K:$K,0) -> 22
B128: Tubes | C128: Compression Molding | D128: Packsys | E128: Mini 120 | F128: 850000 | G128: =_xlfn.XLOOKUP($E$126,Tubes!$D:$D,Tubes!$J:$J,0) -> 20 | H128: =_xlfn.XLOOKUP($E$126,Tubes!$D:$D,Tubes!$K:$K,0) -> 22
B129: Tubes | C129: Compression Molding | D129: Packsys | E129: Mini 300 | F129: 1800000 | G129: =_xlfn.XLOOKUP($E$126,Tubes!$D:$D,Tubes!$J:$J,0) -> 20 | H129: =_xlfn.XLOOKUP($E$126,Tubes!$D:$D,Tubes!$K:$K,0) -> 22
B130: Tubes | C130: Injection Molding | D130: STS | E130: 8005 | F130: 380000 | G130: =_xlfn.XLOOKUP($E$126,Tubes!$D:$D,Tubes!$J:$J,0) -> 20 | H130: =_xlfn.XLOOKUP($E$126,Tubes!$D:$D,Tubes!$K:$K,0) -> 22
B131: Tubes | C131: Injection Molding | D131: AISA | E131: SAESA 100 | F131: 800000 | G131: =_xlfn.XLOOKUP($E$126,Tubes!$D:$D,Tubes!$J:$J,0) -> 20 | H131: =_xlfn.XLOOKUP($E$126,Tubes!$D:$D,Tubes!$K:$K,0) -> 22
B132: Tubes | C132: Injection Molding | D132: AISA | E132: SAESA 120 | F132: 850000 | G132: =_xlfn.XLOOKUP($E$126,Tubes!$D:$D,Tubes!$J:$J,0) -> 20 | H132: =_xlfn.XLOOKUP($E$126,Tubes!$D:$D,Tubes!$K:$K,0) -> 22
B133: Tubes | C133: Injection Molding | D133: AISA | E133: SAESA 240 | F133: 1500000 | G133: =_xlfn.XLOOKUP($E$126,Tubes!$D:$D,Tubes!$J:$J,0) -> 20 | H133: =_xlfn.XLOOKUP($E$126,Tubes!$D:$D,Tubes!$K:$K,0) -> 22
B134: Tubes | C134: Injection Molding | D134: Milacron | E134: Milacron 180 T | F134: 62500 | G134: =_xlfn.XLOOKUP($E$126,Tubes!$D:$D,Tubes!$J:$J,0) -> 20 | H134: =_xlfn.XLOOKUP($E$126,Tubes!$D:$D,Tubes!$K:$K,0) -> 22
B135: Tubes | C135: Injection Molding | D135: Milacron | E135: Milacron 250 T | F135: 66250 | G135: =_xlfn.XLOOKUP($E$126,Tubes!$D:$D,Tubes!$J:$J,0) -> 20 | H135: =_xlfn.XLOOKUP($E$126,Tubes!$D:$D,Tubes!$K:$K,0) -> 22
B136: Tubes | C136: Injection Molding | D136: Milacron | E136: Milacron 350 T | F136: 70000 | G136: =_xlfn.XLOOKUP($E$126,Tubes!$D:$D,Tubes!$J:$J,0) -> 20 | H136: =_xlfn.XLOOKUP($E$126,Tubes!$D:$D,Tubes!$K:$K,0) -> 22
...

Sheet Rigids
A4: Machine Details
A5: Type | B5: Make | C5: Model | D5: Machine Cost € | E5: Power Consumption KWH | F5: Speed | G5: Machine Footprint SQM
A6: EBM | B6: Jomar | C6: Jomar 65 | D6: =(285000+25000)*(100%+$B$70) -> 323485 | E6: 35 | G6: 40
A7: EBM | B7: Jomar | C7: Jomar 135 | D7: =(450000+25000)*(100%+$B$70) -> 495662.5 | E7: 80 | G7: 40
A8: EBM | B8: Uniloy | C8: Uniloy | D8: =(310000+25000)*(100%+$B$70) -> 349572.5 | E8: 65 | G8: 40
A9: EBM | B9: Sika | C9: Sika | D9: =(310000+25000)*(100%+$B$70) -> 349572.5 | E9: 65 | G9: 40
A10: EBM | B10: Speedex | C10: Speedex | D10: =(95000+25000)*(100%+$B$70) -> 125220 | E10: 65 | G10: 40
A11: EBM | B11: Magic | C11: Magic 10 | D11: =(1000000+25000)*(100%+$B$70) -> 1069587.5 | E11: 125 | G11: 40
A12: EBM | B12: BMU | C12: BMU 70 | D12: =(265000*120%+25000)*(100%+$B$70) -> 357920.5 | E12: =35*2 -> 70 | G12: 40
A13: EBM | B13: BMU | C13: BMU 100 | D13: =(550000+25000)*(100%+$B$70) -> 600012.5 | E13: =35*2 -> 70 | G13: 40
A14: EBM | B14: SEB | C14: SEB 820 | D14: =(900000*120%+25000)*(100%+$B$70) -> 1153067.5 | E14: =65*2 -> 130 | G14: 40
A15: EBM | B15: Sidel | C15: Sidel EVO Blow SR 1/2 PH | D15: =(95000+25000)*(100%+$B$70) -> 125220 | E15: 40 | G15: 20
A16: EBM | B16: Bekum | C16: Bekum (dual-head / shuttle & rotary EBM family) | D16: =(350000+25000)*(100%+$B$70) -> 391312.5 | E16: 90 | G16: 50
A17: EBM | B17: Kautex | C17: Kautex / Nissei Kautex (dual-head rotary / shuttle) | D17: =(450000+25000)*(100%+$B$70) -> 495662.5 | E17: 120 | G17: 71.5
A18: EBM | B18: Uniloy | C18: Uniloy (rotary / shuttle EBM families) | D18: =(420000+25000)*(100%+$B$70) -> 464357.5 | E18: 80 | G18: 55
A19: EBM | B19: Jomar | C19: Jomar (shuttle / continuous EBM families) | D19: =(350000+25000)*(100%+$B$70) -> 391312.5 | E19: 85 | G19: 55
A20: EBM | B20: Zhangjiagang / Wuxi / Changsheng | C20: Chinese export OEM — Zhangjiagang / Wuxi / Changsheng (dual-head export models) | D20: =(160000+25000)*(100%+$B$70) -> 193047.5 | E20: 65 | G20: 45
A21: Injection Moulding | B21: Demag | C21: Demag 150 Tonne | D21: =95454.5454545454*120%+$D$48*(1+$B$70) -> 140632.95 | E21: 22 | G21: 40
A22: Injection Moulding | B22: Demag | C22: Demag 250 Tonne | D22: =159090.909090909*120%+$D$48*(1+$B$70) -> 216996.59 | E22: 44 | G22: 40
A23: Injection Moulding | B23: Demag | C23: Demag 300 Tonne | D23: =190909.090909091*120%+$D$48*(1+$B$70) -> 255178.41 | E23: 66 | G23: 40
A24: Injection Moulding | B24: Demag | C24: Demag 350 Tonne | D24: =222727.272727273*120%+$D$48*(1+$B$70) -> 293360.23 | E24: 66 | G24: 40
A25: Injection Moulding | B25: Demag | C25: Demag 400 Tonne | D25: =254545.454545455*120%+$D$48*(1+$B$70) -> 331542.05 | E25: 66 | G25: 40
A26: Injection Moulding | B26: Engel | C26: Engel Victory 220 | D26: =120961.8*120%+$D$48*(1+$B$70) -> 171241.66 | E26: 30 | G26: 40
A27: Injection Moulding | B27: Engel | C27: Engel Victory 300 | D27: =166037.8*120%+$D$48*(1+$B$70) -> 225332.86 | E27: 45 | G27: 40
A28: Injection Moulding | B28: Engel | C28: Engel Victory 400 | D28: =222689.6*120%+$D$48*(1+$B$70) -> 293315.02 | E28: 45 | G28: 40
A29: Injection Moulding | B29: Fanuc | C29: Fanuc 150 Tonne | D29: =136363.636363636*120%+$D$48*(1+$B$70) -> 189723.86 | E29: 20 | G29: 40
A30: Injection Moulding | B30: Fanuc | C30: Fanuc 250 Tonne | D30: =227272.727272727*120%+$D$48*(1+$B$70) -> 298814.77 | E30: 40 | G30: 40
A31: Injection Moulding | B31: Fanuc | C31: Fanuc 300 Tonne | D31: =272727.272727273*120%+$D$48*(1+$B$70) -> 353360.23 | E31: 60 | G31: 40
A32: Injection Moulding | B32: Fanuc | C32: Fanuc 350 Tonne | D32: =318181.818181818*120%+$D$48*(1+$B$70) -> 407905.68 | E32: 60 | G32: 40
A33: Injection Moulding | B33: Fanuc | C33: Fanuc 400 Tonne | D33: =363636.363636364*120%+$D$48*(1+$B$70) -> 462451.14 | E33: 60 | G33: 40
A34: Injection Moulding | B34: Ferromatik | C34: Ferromatik K-TEC 155 Tonne | D34: =108700*120%+$D$48*(1+$B$70) -> 156527.5 | E34: 19 | G34: 40
A35: Injection Moulding | B35: Ferromatik | C35: Ferromatik K-TEC 200 Tonne | D35: =130000*120%+$D$48*(1+$B$70) -> 182087.5 | E35: 20 | G35: 40
A36: Injection Moulding | B36: Ferromatik | C36: Ferromatik K-TEC 250 Tonne | D36: =146900*120%+$D$48*(1+$B$70) -> 202367.5 | E36: 22 | G36: 40
A37: Injection Moulding | B37: Ferromatik | C37: Ferromatik K-TEC 275 Tonne | D37: =151400*120%+$D$48*(1+$B$70) -> 207767.5 | E37: 22 | G37: 40
A38: Injection Moulding | B38: Ferromatik | C38: Ferromatik K-TEC 320 Tonne | D38: =167700*120%+$D$48*(1+$B$70) -> 227327.5 | E38: 28 | G38: 40
A39: Injection Moulding | B39: Ferromatik | C39: Ferromatik K-TEC 350 Tonne | D39: =178600*120%+$D$48*(1+$B$70) -> 240407.5 | E39: 28 | G39: 40
A40: Injection Moulding | B40: Ferromatik | C40: Ferromatik K-TEC 400 Tonne | D40: =210500*120%+$D$48*(1+$B$70) -> 278687.5 | E40: 40 | G40: 40
A41: Injection Moulding | B41: Ferromatik | C41: Ferromatik K-TEC 450 Tonne | D41: =223300*120%+$D$48*(1+$B$70) -> 294047.5 | E41: 40 | G41: 40
A42: Injection Moulding | B42: Husky | C42: Husky 150 Tonne | D42: =150000*120%+$D$48*(1+$B$70) -> 206087.5 | E42: 20 | G42: 40
A43: Injection Moulding | B43: Husky | C43: Husky 200 Tonne | D43: =200000*120%+$D$48*(1+$B$70) -> 266087.5 | E43: 40 | G43: 40
...

Sheet Flexibles
A3: Machine Details
A4: Type | B4: Make | C4: Model | D4: Machine Cost € | E4: Line Speed (Mtr/ Min) | F4: Machine Width (Mtr) | G4: Power Consumption KWH | H4: Machine Footprint SQM | I4: Line Speed at start (Mtr/ Min)
A5: Gravure | B5: Bobst | C5: Bobst Lemanic Delta | D5: 3000000 | E5: 250 | F5: 0.82 | G5: 180 | H5: 210 | I5: =E5*5% -> 12.5
A6: Gravure | B6: Bobst | C6: Bobst Lemanic Rivera | D6: 3000000 | E6: 400 | F6: 0.81 | G6: 180 | H6: 240 | I6: =E6*5% -> 20
A7: Gravure | B7: Bobst | C7: Bobst RS6003 Expert | D7: 2500000 | E7: 450 | F7: 1.02 | G7: 180 | H7: 154 | I7: =E7*5% -> 22.5
A8: Gravure | B8: Bobst | C8: Bobst RS5003 Expert | D8: 2500000 | E8: 450 | F8: 0.92 | G8: 180 | H8: 120 | I8: =E8*5% -> 22.5
A9: Gravure | B9: Bobst | C9: Bobst Expert MW 60 I 80 | D9: 1800000 | E9: 300 | F9: 0.8 | G9: 180 | H9: 110 | I9: =E9*5% -> 15
A10: Gravure | B10: Bobst | C10: Bobst Expert GP 500 | D10: 1800000 | E10: 450 | F10: 2.4 | G10: 180 | H10: 180 | I10: =E10*5% -> 22.5
A11: Gravure | B11: Bobst | C11: Bobst Expert GP 700 | D11: 1800000 | E11: 450 | F11: 2.4 | G11: 180 | H11: 208 | I11: =E11*5% -> 22.5
A12: Gravure | B12: Miraflex | C12: Miraflex 70+ M | D12: 1500000 | E12: 450 | F12: 1.45 | G12: 180 | H12: 56 | I12: =E12*5% -> 22.5
A13: Gravure | B13: Miraflex | C13: Miraflex 70+ L | D13: 1500000 | E13: 550 | F13: 1.45 | G13: 180 | H13: 56 | I13: =E13*5% -> 27.5
A14: Gravure | B14: Cerutti | C14: Cerutti R982 | D14: 1800000 | E14: 380 | F14: 1.3 | G14: 180 | H14: 81 | I14: =E14*5% -> 19
A15: Gravure | B15: Huitong | C15: Huitong HD-Type ELS | D15: 1800000 | E15: 320 | F15: 1.3 | G15: 180 | H15: 90 | I15: =E15*5% -> 16
A16: Gravure | B16: Huitong | C16: Huitong ZD-Type ELS | D16: 1450000 | E16: 280 | F16: 1.25 | G16: 180 | H16: 90 | I16: =E16*5% -> 14
... A57: Pouching | B57: Yousheng | C57: Yousheng | D57: 100000 | E57: 25 | F57: 1.2 | G57: 55 | H57: 32 | I57: =E57*5% -> 1.25
A58: Pouching | B58: Galaxy | C58: Galaxy GS 24 TSG | D58: 90000 | E58: 87 | G58: 45.5 | H58: 32 | I58: 8.7
A59: Spouting | B59: Karlville | C59: Karlville ST - 1L | D59: 45000 | E59: 50 | G59: 8 | H59: 20 | I59: 5
A60: Spouting | B60: Spaldopack | C60: Spaldopack SI - 60 | D60: 45000 | E60: 60 | G60: 8 | H60: 20 | I60: 6
A61: Spouting | B61: Totani | C61: Totani ST - 30 | D61: 40000 | E61: 60 | G61: 8 | H61: 20 | I61: 6
A62: Spouting | B62: Galaxy | C62: Galaxy GSF-12 | D62: 35000 | E62: 45 | G62: 8 | H62: 20 | I62: 4.5
A63: Spouting | B63: Haosen | C63: Haosen HS-XZD-1800C | D63: 20000 | E63: 30 | G63: 8 | H63: 20 | I63: 3
A64: Blown Film Line | B64: Reifenhauser | C64: Reifenhauser 3 Layer | D64: 2000000 | E64: 700 | G64: 380 | H64: 230 | I64: 70
A65: Blown Film Line | B65: Reifenhauser | C65: Reifenhauser 5 Layer | D65: 2500000 | E65: 500 | G65: 450 | H65: 260 | I65: 50
A66: Blown Film Line | B66: Reifenhauser | C66: Reifenhauser 7 Layer | D66: 3500000 | E66: 300 | G66: 550 | H66: 300 | I66: 30
A67: Blown Film Line | B67: Windmoller & Holscher | C67: Windmoller & Holscher 3 layer | D67: 2200000 | E67: 750 | G67: 400 | H67: 230 | I67: 75
A68: Blown Film Line | B68: Windmoller & Holscher | C68: Windmoller & Holscher 5 layer | D68: 3000000 | E68: 550 | G68: 480 | H68: 270 | I68: 55
A69: Blown Film Line | B69: Bandera | C69: Bandera 3 Layer | D69: 1200000 | E69: 600 | G69: 360 | H69: 210 | I69: 60
A70: Blown Film Line | B70: Bandera | C70: Bandera 5 Layer | D70: 1800000 | E70: 500 | G70: 420 | H70: 240 | I70: 50
A71: Glueing | B71: Karlville | C71: Karlville K2 | D71: 100000 | E71: 300 | G71: 12 | H71: 9.6
A72: Glueing | B72: Karlville | C72: Karlville K5 | D72: 180000 | E72: 500 | G72: 12 | H72: 9.6
A73: Glueing | B73: Fuji | C73: Fuji Seal | D73: 250000 | E73: 400 | G73: 20 | H73: 28
A74: Glueing | B74: Galaxy | C74: Galaxy Packtech— GSF | D74: 40000 | E74: 300 | G74: 8 | H74: 17.5
A75: Glueing | B75: Kegu / Sunfeng | C75: Kegu / Sunfeng | D75: 45000 | E75: 400 | G75: 8 | H75: 9.6
A76: Glueing | B76: KETE | C76: KETE | D76: 30000 | E76: 200 | G76: 5 | H76: 9.6

Sheet Tubes
A3: Machine Details:
A4: Type | B4: Tech | C4: Make | D4: Model | E4: Machine Cost € | F4: Line Speed Tubes/Min | G4: Machine Width (mm) | H4: Changeparts € | I4: Capping Changeparts € | J4: Machine Footprint SQM | K4: Energy KWH | L4: Annual Capacity
A5: Tubing Lines | B5: Compression Molding | C5: Packsys | D5: Focus 40 | E5: =0.9*10^6 -> 900000 | F5: 125 | H5: =E5*10% -> 90000 | I5: =70*10^5/90 -> 77777.778 | J5: 20 | K5: 22 | L5: 47.52
B6: Compression Molding | C6: Packsys | D6: Focus 80 | E6: =1.5*10^6 -> 1500000 | F6: 250 | H6: =E6*10% -> 150000 | I6: =70*10^5/90 -> 77777.778 | J6: 20 | K6: 25 | L6: 95.04
B7: Compression Molding | C7: Packsys | D7: Mini 120 | E7: 850000 | F7: 120 | H7: =E7*10% -> 85000 | I7: =70*10^5/90 -> 77777.778 | J7: 15 | K7: 22 | L7: 45.6192
B8: Compression Molding | C8: Packsys | D8: Mini 300 | E8: =1.8*10^6 -> 1800000 | F8: 300 | H8: =E8*10% -> 180000 | I8: =70*10^5/90 -> 77777.778 | J8: 25 | K8: 30 | L8: 114.048
B9: Injection Molding | C9: STS | D9: 8005 | E9: 380000 | F9: 90 | H9: =E9*10% -> 38000 | I9: =50*10^5/90 -> 55555.556 | J9: 15 | K9: 22 | L9: 34.2144
B10: Injection Molding | C10: AISA | D10: SAESA 100 | E10: =800000 -> 800000 | F10: 100 | H10: =E10*10% -> 80000 | I10: =70*10^5/90 -> 77777.778 | J10: 15 | K10: 22 | L10: 38.016
B11: Injection Molding | C11: AISA | D11: SAESA 120 | E11: =850000 -> 850000 | F11: 120 | H11: =E11*10% -> 85000 | I11: =70*10^5/90 -> 77777.778 | J11: 15 | K11: 22 | L11: 45.6192
B12: Injection Molding | C12: AISA | D12: SAESA 240 | E12: =1.5*10^6 -> 1500000 | F12: 240 | H12: =E12*10% -> 150000 | I12: =70*10^5/90 -> 77777.778 | J12: 20 | K12: 25 | L12: 91.2384
A13: Injection Moulding | B13: Injection Molding | J13: 30 | K13: 22.8
B14: NA | C14: Milacron | D14: Milacron 180 T | E14: =(50000)*125% -> 62500 | J14: 30 | K14: 22.8
B15: NA | C15: Milacron | D15: Milacron 250 T | E15: =(53000)*125% -> 66250 | J15: 30 | K15: 27.8
B16: NA | C16: Milacron | D16: Milacron 350 T | E16: =(56000)*125% -> 70000 | J16: 30 | K16: 31
B17: NA | C17: Elaxis Demag | D17: Elaxis 180 Ton | E17: =E14 -> 62500 | J17: 30 | K17: 22.8
B18: NA | C18: Elaxis Demag | D18: Elaxis 250 Ton | E18: =E15 -> 66250 | J18: 30 | K18: 27.8
A19: Printing Lines | B19: Flexo | J19: 30 | K19: 35
B20: Flexo | C20: Nilpeter | D20: FA Line | E20: =1.2*10^6 -> 1200000 | F20: 200 | G20: 0.355 | J20: 30 | K20: 35 | L20: =F20*G20*60*24*80%*330 -> 26991360
B21: Flexo | C21: Gallus | D21: ECS 340 | E21: =0.9*10^6 -> 900000 | F21: 165 | G21: 0.34 | J21: 30 | K21: 35 | L21: =F21*G21*60*24*80%*330 -> 21326976
J22: 30 | K22: 35 | L22: =F22*G22*60*24*80%*330 -> 0

Sheet Corrugates
A3: Type | B3: Make | C3: Model | D3: Machine Cost € | E3: Line Speed (Mtr/ Min) | F3: Machine Width (Mtr) | G3: Power Consumption KWH | H3: Machine Footprint SQM
A4: Corrugation Line | B4: HSIEH HSU | C4: HSIEH HSU | D4: 1800000 | E4: 250 | F4: 1.8 | G4: 340 | H4: 450
A5: Corrugation Line | B5: TCY | C5: TCY QSS 250 | D5: 1800000 | E5: 250 | F5: 1.8 | G5: 340 | H5: 450
A6: Corrugation Line | B6: TCY | C6: TCY QSS 300 | D6: 1800000 | E6: 300 | F6: 1.8 | G6: 340 | H6: 450
A7: Corrugation Line | B7: TCY | C7: TCY QSS 350 | D7: 1800000 | E7: 350 | F7: 1.8 | G7: 340 | H7: 450
A8: Corrugation Line | B8: BHS | C8: BHS Eco Line | D8: 2950000 | E8: 150 | F8: 1.8 | G8: 340 | H8: 450
A9: Corrugation Line | B9: BHS | C9: BHS S line | D9: 3950000 | E9: 250 | F9: 2.2 | G9: 340 | H9: 450
A10: Corrugation Line | B10: Fosver | C10: Fosver S line | D10: 4750000 | E10: 370 | F10: 2.4 | G10: 340 | H10: 450
A11: Corrugation Line | B11: Fosver | C11: Fosver Pro Line | D11: 3950000 | E11: 270 | F11: 2.4 | G11: 340 | H11: 450
A12: Corrugation Line | B12: Mitsubishi | C12: Mitsubishi SH 400 | D12: 5950000 | E12: 400 | F12: 2.4 | G12: 340 | H12: 450
A13: Printing Machine | B13: TCY | C13: TCY 6 PA + RDC | D13: 500000 | E13: 70 | F13: 2.1 | G13: 80 | H13: 150
A14: Printing Machine | B14: Langston | C14: Langston 50x113 (2C) | D14: 977500 | E14: 50 | F14: 2.1 | G14: 80 | H14: 150
A15: Printing Machine | B15: Sunrise | C15: SUNRISE PACIFIC 1227 | D15: 750000 | E15: 224 | F15: 1.272 | G15: 80 | H15: 150
... A19: Rotary Die Cutter | B19: Bobst | C19: Bobst | D19: 500000 | E19: 8000 | F19: 2.8 | G19: 80 | H19: 100
A20: Rotary Die Cutter | B20: Lian Tee | C20: Lian Tiee PS-1836 +RDC | D20: 350000 | E20: 9000 | G20: 80 | H20: 100
A21: Rotary Die Cutter | B21: Lian Tee | C21: Lian Tiee PS-1628 +RDC | D21: 300000 | E21: 9000 | G21: 80 | H21: 100
A22: Rotary Die Cutter | B22: TCY | C22: TCY 6 PA + RDC | D22: 500000 | E22: 15000 | G22: 80 | H22: 100
A23: Rotary Die Cutter | B23: TCY | C23: TCY 8 PA + RDC | D23: 550000 | E23: 9000 | G23: 80 | H23: 100
A24: Rotary Die Cutter | B24: TCY | C24: TCY 11 PA Inline | D24: 650000 | E24: 6000 | G24: 80 | H24: 100
A25: Rotary Die Cutter | B25: Ward | C25: Ward 66x100 | D25: 90000 | E25: 5000 | F25: 2.8 | G25: 80 | H25: 100
A26: Rotary Die Cutter | B26: Titan | C26: Titan 63x104 (4C) | D26: 80000 | E26: 5700 | F26: 1 | G26: 80 | H26: 100
A27: Rotary Die Cutter | B27: Ward | C27: Ward 63x120 (3C) | D27: 80000 | E27: 6000 | F27: 1.2 | G27: 80 | H27: 100
A28: Rotary Die Cutter | B28: Bobst | C28: Bobst 1628 DRO NT RS | D28: 850000 | E28: 11000 | G28: 80 | H28: 100
A29: Rotary Die Cutter | B29: Bobst | C29: Bobst 1228 NT RS | D29: 700000 | E29: 10000 | G29: 80 | H29: 100
A30: Rotary Die Cutter | B30: Mitsubishi | C30: MitsubEvol 37x100 (4C) | D30: 760000 | E30: 7000 | F30: 1 | G30: 80 | H30: 100
A31: Rotary Die Cutter | B31: Mitsubishi | C31: MitsubEvol (34/84) (4C) | D31: 660000 | E31: 6000 | F31: 0.8 | G31: 80 | H31: 100
A32: Flat Bed Die Cutter | B32: BOBst | C32: BOBst Mastercut 1.7/2.1 | D32: 800000 | E32: 7000 | G32: 100 | H32: 150
A33: Flat Bed Die Cutter | B33: BOBst | C33: BOBST Eterna E cut 1060 | D33: 750000 | E33: 2500 | G33: 100 | H33: 150
A34: Flat Bed Die Cutter | B34: BOBst | C34: Emba 245 Ultima | D34: 722891.57 | E34: 18000 | G34: 100 | H34: 150
A35: Flat Bed Die Cutter | B35: Mitsubishi | C35: Mitsubishi MTR - 1600 | D35: 1000000 | E35: 16000 | G35: 100 | H35: 150
A36: Former & Gluer | B36: Bobst | C36: Bobst/BGM | D36: 1000000 | E36: 18000 | G36: 80 | H36: 300
A37: Former & Gluer | B37: Bobst | C37: BOBST FFG 1632 | 1636 NT RS | D37: 1000000 | E37: 15000 | G37: 80 | H37: 300
A38: Former & Gluer | B38: Bobst | C38: Bobst 1228 NT RS | D38: 850000 | E38: 13000 | G38: 80 | H38: 300
A39: Former & Gluer | B39: Mitsubishi | C39: Evol 84 (4C) | D39: 1200000 | E39: 24000 | G39: 80 | H39: 300
A40: Former & Gluer | B40: Mitsubishi | C40: Evol 100 (4C) | D40: 1200000 | E40: 21000 | G40: 80 | H40: 300
A41: Former & Gluer | B41: Mitsubishi | C41: Evol 115 (4C) | D41: 1200000 | E41: 19800 | G41: 80 | H41: 300

Sheet Cartons
A3: Machine Details
A4: Details | B4: Machine Model | C4: Cost Per Machine € | D4: Line Speed (Sheets/ Hour) | E4: Power Consumption (KwH) | F4: Machine Footprint SQM
A5: Printing | B5: KBA 8000 | C5: 800000 | D5: 12000 | E5: 150 | F5: 250
A6: Printing | B6: Heidelberg Speedmaster SM 52 | C6: 200000 | D6: 8000 | E6: 150 | F6: 250
A7: Printing | B7: Heidelberg Speedmaster SM 74 / XL 75 | C7: 350000 | D7: 12000 | E7: 150 | F7: 250
A8: Printing | B8: Heidelberg Speedmaster SM 102 / XL 106 | C8: 800000 | D8: 14000 | E8: 150 | F8: 250
A9: Printing | B9: KBA Rapida 75 | C9: 400000 | D9: 10000 | E9: 150 | F9: 250
A10: Printing | B10: KBA Rapida 106 | C10: 750000 | D10: 12000 | E10: 150 | F10: 250
A11: Printing | B11: Komori Lithrone G / GL series | C11: 600000 | D11: 12000 | E11: 150 | F11: 250
A12: Printing | B12: Manroland R700 series | C12: 300000 | D12: 8000 | E12: 150 | F12: 250
A13: Printing | B13: Manroland R900 series | C13: 800000 | D13: 15000 | E13: 150 | F13: 250
A14: Printing | B14: Mitsubishi Diamond / high-quality sheetfed
A15: Spot Varnish | B15: Unison | C15: 120000 | D15: 5000 | E15: 20 | F15: 50
A16: Spot Varnish | B16: MGI JETvarnish 3D | C16: 500000 | D16: 4000 | E16: 20 | F16: 50
A17: Spot Varnish | B17: Scodix Scodix Ultra / Scodix SENSE | C17: 500000 | D17: 4000 | E17: 20 | F17: 50
A18: Spot Varnish | B18: Heidelberg Speedmaster | C18: 150000 | D18: 8000 | E18: 20 | F18: 50
A19: Spot Varnish | B19: Komori | C19: 100000 | D19: 8000 | E19: 20 | F19: 50
A20: Spot Varnish | B20: KBA Rapida | C20: 2,00,000 | D20: 8000 | E20: 20 | F20: 50
A21: Spot Varnish | B21: Bobst | C21: 250000 | D21: 8400 | E21: 20 | F21: 50
A22: Hot Foiling | B22: Hot Foil Machine | C22: 250000 | D22: 5000 | E22: 50 | F22: 100
A23: Lamination | B23: Lamination Machine | C23: 65000 | D23: 5000 | E23: 50 | F23: 50
A24: Lamination | B24: Kompac KwikPrint / EZ Koat | C24: 150000 | D24: 60 | E24: 20 | F24: 50
A25: Lamination | B25: Billhöfer Eco 66, Eco 76, Eco | C25: 450000 | D25: 120 | E25: 60 | F25: 50
A26: Lamination | B26: Lamina Lamina Blackline, SA, FA, FA Blackline | C26: 600000 | D26: 160 | E26: 70 | F26: 50
A27: Lamination | B27: Tunkers Variowell / Sheetmaster | C27: 450000 | D27: 140 | E27: 50 | F27: 50
A28: Lamination | B28: Billhöfer Wet-Lam series | C28: 400000 | D28: 90 | E28: 45 | F28: 50
A29: Lamination | B29: JMD Machinery FMZ Series | C29: 90000 | D29: 90 | E29: 30 | F29: 50
A30: Lamination | B30: Hongming HM Series | C30: 150000 | D30: 120 | E30: 55 | F30: 50
A31: Lamination | B31: Jiawei JW Series | C31: 100000 | D31: 80 | E31: 40 | F31: 50
A32: Lamination | B32: Wanlian Machinery WL Series | C32: 80000 | D32: 100 | E32: 35 | F32: 50
... A36: Folder - Gluer | B36: Bobst Masterfold | C36: 600000 | D36: 120000 | E36: 50 | F36: 250

Sheet PCR
A3: Machine Details
A4: Type | B4: Machine Model | C4: Output Kg/Hr | D4: Cost €
A5: Extrusion Line | B5: Erema | C5: 1250 | D5: =4408061*(1+$B$24) -> 4599811.7 | E5: * Including SSP line
A6: Extrusion Line | B6: Starlinger recoSTAR PET 165 art | C6: 2040 | D6: =6365010*(1+$B$24) -> 6641887.9 | E6: * Including SSP line
A7: Washing - Hot Wash / Drying | B7: Sorema | C7: 2200 | D7: =297700 -> 297700 | E7: * Label & Cap Removal Machine
A8: Sorting Waste Plastic | B8: Ishinta | C8: 5000 | D8: =750000 -> 750000 | E8: * 3 Sets of Machines
A9: AI Waste Analyser | B9: Grey Parrot | C9: 1250 | D9: =60000*5*(1+$B$24) -> 313050 | E9: * to Match the extruder capacity as it has no capacity as such; 5 Analyser for the entire line
A10: Total | D10: =SUM(D5:D9) -> 12602450
A13: Break Up of charges on Machine Imported | C13: ** Import Duty not added as usually it is allowable as deduction from Local authorities for business development
A15: Import Duty | B15: 0
A16: International Freight | B16: 0.005
A17: Insurance | B17: 0.0007
A18: Shipping line & Port charges | B18: 0.0002
A19: Detention charges | B19: 0.0008
A20: CHA charegs | B20: 0.0011
A21: Local Freight | B21: 0.0007
A22: Installation & Commissioning | B22: 0.01
A23: Bank Charges | B23: 0.025
A24: Total | B24: =SUM(B15:B23) -> 0.0435
